{
 "cells": [
  {
   "cell_type": "code",
   "execution_count": 1,
   "metadata": {},
   "outputs": [
    {
     "name": "stdout",
     "output_type": "stream",
     "text": [
      "Requirement already satisfied: SimpleITK in /opt/anaconda3/lib/python3.8/site-packages (2.1.0)\n",
      "Requirement already satisfied: dltk in /opt/anaconda3/lib/python3.8/site-packages (0.2.1)\n",
      "Requirement already satisfied: numpy>=1.14.0 in /opt/anaconda3/lib/python3.8/site-packages (from dltk) (1.19.2)\n",
      "Requirement already satisfied: future>=0.16.0 in /opt/anaconda3/lib/python3.8/site-packages (from dltk) (0.18.2)\n",
      "Requirement already satisfied: scipy>=0.19.0 in /opt/anaconda3/lib/python3.8/site-packages (from dltk) (1.5.2)\n",
      "Requirement already satisfied: SimpleITK>=1.0.0 in /opt/anaconda3/lib/python3.8/site-packages (from dltk) (2.1.0)\n",
      "Requirement already satisfied: jupyter>=1.0.0 in /opt/anaconda3/lib/python3.8/site-packages (from dltk) (1.0.0)\n",
      "Requirement already satisfied: scikit-image>=0.13.0 in /opt/anaconda3/lib/python3.8/site-packages (from dltk) (0.17.2)\n",
      "Requirement already satisfied: pandas>=0.19.0 in /opt/anaconda3/lib/python3.8/site-packages (from dltk) (1.1.3)\n",
      "Requirement already satisfied: xlrd>=1.1.0 in /opt/anaconda3/lib/python3.8/site-packages (from dltk) (1.2.0)\n",
      "Requirement already satisfied: argparse in /opt/anaconda3/lib/python3.8/site-packages (from dltk) (1.4.0)\n",
      "Requirement already satisfied: matplotlib>=1.5.3 in /opt/anaconda3/lib/python3.8/site-packages (from dltk) (3.3.2)\n",
      "Requirement already satisfied: ipykernel in /opt/anaconda3/lib/python3.8/site-packages (from jupyter>=1.0.0->dltk) (5.3.4)\n",
      "Requirement already satisfied: nbconvert in /opt/anaconda3/lib/python3.8/site-packages (from jupyter>=1.0.0->dltk) (6.0.7)\n",
      "Requirement already satisfied: ipywidgets in /opt/anaconda3/lib/python3.8/site-packages (from jupyter>=1.0.0->dltk) (7.5.1)\n",
      "Requirement already satisfied: notebook in /opt/anaconda3/lib/python3.8/site-packages (from jupyter>=1.0.0->dltk) (6.1.4)\n",
      "Requirement already satisfied: qtconsole in /opt/anaconda3/lib/python3.8/site-packages (from jupyter>=1.0.0->dltk) (4.7.7)\n",
      "Requirement already satisfied: jupyter-console in /opt/anaconda3/lib/python3.8/site-packages (from jupyter>=1.0.0->dltk) (6.2.0)\n",
      "Requirement already satisfied: networkx>=2.0 in /opt/anaconda3/lib/python3.8/site-packages (from scikit-image>=0.13.0->dltk) (2.5)\n",
      "Requirement already satisfied: pillow!=7.1.0,!=7.1.1,>=4.3.0 in /opt/anaconda3/lib/python3.8/site-packages (from scikit-image>=0.13.0->dltk) (8.0.1)\n",
      "Requirement already satisfied: imageio>=2.3.0 in /opt/anaconda3/lib/python3.8/site-packages (from scikit-image>=0.13.0->dltk) (2.9.0)\n",
      "Requirement already satisfied: tifffile>=2019.7.26 in /opt/anaconda3/lib/python3.8/site-packages (from scikit-image>=0.13.0->dltk) (2020.10.1)\n",
      "Requirement already satisfied: PyWavelets>=1.1.1 in /opt/anaconda3/lib/python3.8/site-packages (from scikit-image>=0.13.0->dltk) (1.1.1)\n",
      "Requirement already satisfied: pytz>=2017.2 in /opt/anaconda3/lib/python3.8/site-packages (from pandas>=0.19.0->dltk) (2020.1)\n",
      "Requirement already satisfied: python-dateutil>=2.7.3 in /opt/anaconda3/lib/python3.8/site-packages (from pandas>=0.19.0->dltk) (2.8.1)\n",
      "Requirement already satisfied: cycler>=0.10 in /opt/anaconda3/lib/python3.8/site-packages (from matplotlib>=1.5.3->dltk) (0.10.0)\n",
      "Requirement already satisfied: certifi>=2020.06.20 in /opt/anaconda3/lib/python3.8/site-packages (from matplotlib>=1.5.3->dltk) (2020.6.20)\n",
      "Requirement already satisfied: kiwisolver>=1.0.1 in /opt/anaconda3/lib/python3.8/site-packages (from matplotlib>=1.5.3->dltk) (1.3.0)\n",
      "Requirement already satisfied: pyparsing!=2.0.4,!=2.1.2,!=2.1.6,>=2.0.3 in /opt/anaconda3/lib/python3.8/site-packages (from matplotlib>=1.5.3->dltk) (2.4.7)\n",
      "Requirement already satisfied: ipython>=5.0.0 in /opt/anaconda3/lib/python3.8/site-packages (from ipykernel->jupyter>=1.0.0->dltk) (7.19.0)\n",
      "Requirement already satisfied: appnope; platform_system == \"Darwin\" in /opt/anaconda3/lib/python3.8/site-packages (from ipykernel->jupyter>=1.0.0->dltk) (0.1.0)\n",
      "Requirement already satisfied: jupyter-client in /opt/anaconda3/lib/python3.8/site-packages (from ipykernel->jupyter>=1.0.0->dltk) (6.1.7)\n",
      "Requirement already satisfied: traitlets>=4.1.0 in /opt/anaconda3/lib/python3.8/site-packages (from ipykernel->jupyter>=1.0.0->dltk) (5.0.5)\n",
      "Requirement already satisfied: tornado>=4.2 in /opt/anaconda3/lib/python3.8/site-packages (from ipykernel->jupyter>=1.0.0->dltk) (6.0.4)\n",
      "Requirement already satisfied: pygments>=2.4.1 in /opt/anaconda3/lib/python3.8/site-packages (from nbconvert->jupyter>=1.0.0->dltk) (2.7.2)\n",
      "Requirement already satisfied: pandocfilters>=1.4.1 in /opt/anaconda3/lib/python3.8/site-packages (from nbconvert->jupyter>=1.0.0->dltk) (1.4.3)\n",
      "Requirement already satisfied: bleach in /opt/anaconda3/lib/python3.8/site-packages (from nbconvert->jupyter>=1.0.0->dltk) (3.2.1)\n",
      "Requirement already satisfied: nbclient<0.6.0,>=0.5.0 in /opt/anaconda3/lib/python3.8/site-packages (from nbconvert->jupyter>=1.0.0->dltk) (0.5.1)\n",
      "Requirement already satisfied: jupyterlab-pygments in /opt/anaconda3/lib/python3.8/site-packages (from nbconvert->jupyter>=1.0.0->dltk) (0.1.2)\n",
      "Requirement already satisfied: mistune<2,>=0.8.1 in /opt/anaconda3/lib/python3.8/site-packages (from nbconvert->jupyter>=1.0.0->dltk) (0.8.4)\n",
      "Requirement already satisfied: nbformat>=4.4 in /opt/anaconda3/lib/python3.8/site-packages (from nbconvert->jupyter>=1.0.0->dltk) (5.0.8)\n",
      "Requirement already satisfied: testpath in /opt/anaconda3/lib/python3.8/site-packages (from nbconvert->jupyter>=1.0.0->dltk) (0.4.4)\n",
      "Requirement already satisfied: jinja2>=2.4 in /opt/anaconda3/lib/python3.8/site-packages (from nbconvert->jupyter>=1.0.0->dltk) (2.11.2)\n",
      "Requirement already satisfied: entrypoints>=0.2.2 in /opt/anaconda3/lib/python3.8/site-packages (from nbconvert->jupyter>=1.0.0->dltk) (0.3)\n",
      "Requirement already satisfied: jupyter-core in /opt/anaconda3/lib/python3.8/site-packages (from nbconvert->jupyter>=1.0.0->dltk) (4.6.3)\n",
      "Requirement already satisfied: defusedxml in /opt/anaconda3/lib/python3.8/site-packages (from nbconvert->jupyter>=1.0.0->dltk) (0.6.0)\n",
      "Requirement already satisfied: widgetsnbextension~=3.5.0 in /opt/anaconda3/lib/python3.8/site-packages (from ipywidgets->jupyter>=1.0.0->dltk) (3.5.1)\n",
      "Requirement already satisfied: pyzmq>=17 in /opt/anaconda3/lib/python3.8/site-packages (from notebook->jupyter>=1.0.0->dltk) (19.0.2)\n",
      "Requirement already satisfied: prometheus-client in /opt/anaconda3/lib/python3.8/site-packages (from notebook->jupyter>=1.0.0->dltk) (0.8.0)\n",
      "Requirement already satisfied: Send2Trash in /opt/anaconda3/lib/python3.8/site-packages (from notebook->jupyter>=1.0.0->dltk) (1.5.0)\n",
      "Requirement already satisfied: ipython-genutils in /opt/anaconda3/lib/python3.8/site-packages (from notebook->jupyter>=1.0.0->dltk) (0.2.0)\n",
      "Requirement already satisfied: argon2-cffi in /opt/anaconda3/lib/python3.8/site-packages (from notebook->jupyter>=1.0.0->dltk) (20.1.0)\n",
      "Requirement already satisfied: terminado>=0.8.3 in /opt/anaconda3/lib/python3.8/site-packages (from notebook->jupyter>=1.0.0->dltk) (0.9.1)\n",
      "Requirement already satisfied: qtpy in /opt/anaconda3/lib/python3.8/site-packages (from qtconsole->jupyter>=1.0.0->dltk) (1.9.0)\n",
      "Requirement already satisfied: prompt-toolkit!=3.0.0,!=3.0.1,<3.1.0,>=2.0.0 in /opt/anaconda3/lib/python3.8/site-packages (from jupyter-console->jupyter>=1.0.0->dltk) (3.0.8)\n",
      "Requirement already satisfied: decorator>=4.3.0 in /opt/anaconda3/lib/python3.8/site-packages (from networkx>=2.0->scikit-image>=0.13.0->dltk) (4.4.2)\n",
      "Requirement already satisfied: six>=1.5 in /opt/anaconda3/lib/python3.8/site-packages (from python-dateutil>=2.7.3->pandas>=0.19.0->dltk) (1.15.0)\n",
      "Requirement already satisfied: setuptools>=18.5 in /opt/anaconda3/lib/python3.8/site-packages (from ipython>=5.0.0->ipykernel->jupyter>=1.0.0->dltk) (50.3.1.post20201107)\n",
      "Requirement already satisfied: backcall in /opt/anaconda3/lib/python3.8/site-packages (from ipython>=5.0.0->ipykernel->jupyter>=1.0.0->dltk) (0.2.0)\n",
      "Requirement already satisfied: jedi>=0.10 in /opt/anaconda3/lib/python3.8/site-packages (from ipython>=5.0.0->ipykernel->jupyter>=1.0.0->dltk) (0.17.1)\n",
      "Requirement already satisfied: pickleshare in /opt/anaconda3/lib/python3.8/site-packages (from ipython>=5.0.0->ipykernel->jupyter>=1.0.0->dltk) (0.7.5)\n",
      "Requirement already satisfied: pexpect>4.3; sys_platform != \"win32\" in /opt/anaconda3/lib/python3.8/site-packages (from ipython>=5.0.0->ipykernel->jupyter>=1.0.0->dltk) (4.8.0)\n",
      "Requirement already satisfied: webencodings in /opt/anaconda3/lib/python3.8/site-packages (from bleach->nbconvert->jupyter>=1.0.0->dltk) (0.5.1)\n",
      "Requirement already satisfied: packaging in /opt/anaconda3/lib/python3.8/site-packages (from bleach->nbconvert->jupyter>=1.0.0->dltk) (20.4)\n",
      "Requirement already satisfied: nest-asyncio in /opt/anaconda3/lib/python3.8/site-packages (from nbclient<0.6.0,>=0.5.0->nbconvert->jupyter>=1.0.0->dltk) (1.4.2)\n",
      "Requirement already satisfied: async-generator in /opt/anaconda3/lib/python3.8/site-packages (from nbclient<0.6.0,>=0.5.0->nbconvert->jupyter>=1.0.0->dltk) (1.10)\n",
      "Requirement already satisfied: jsonschema!=2.5.0,>=2.4 in /opt/anaconda3/lib/python3.8/site-packages (from nbformat>=4.4->nbconvert->jupyter>=1.0.0->dltk) (3.2.0)\n",
      "Requirement already satisfied: MarkupSafe>=0.23 in /opt/anaconda3/lib/python3.8/site-packages (from jinja2>=2.4->nbconvert->jupyter>=1.0.0->dltk) (1.1.1)\n",
      "Requirement already satisfied: cffi>=1.0.0 in /opt/anaconda3/lib/python3.8/site-packages (from argon2-cffi->notebook->jupyter>=1.0.0->dltk) (1.14.3)\n",
      "Requirement already satisfied: ptyprocess in /opt/anaconda3/lib/python3.8/site-packages (from terminado>=0.8.3->notebook->jupyter>=1.0.0->dltk) (0.6.0)\n",
      "Requirement already satisfied: wcwidth in /opt/anaconda3/lib/python3.8/site-packages (from prompt-toolkit!=3.0.0,!=3.0.1,<3.1.0,>=2.0.0->jupyter-console->jupyter>=1.0.0->dltk) (0.2.5)\n",
      "Requirement already satisfied: parso<0.8.0,>=0.7.0 in /opt/anaconda3/lib/python3.8/site-packages (from jedi>=0.10->ipython>=5.0.0->ipykernel->jupyter>=1.0.0->dltk) (0.7.0)\n",
      "Requirement already satisfied: pyrsistent>=0.14.0 in /opt/anaconda3/lib/python3.8/site-packages (from jsonschema!=2.5.0,>=2.4->nbformat>=4.4->nbconvert->jupyter>=1.0.0->dltk) (0.17.3)\n",
      "Requirement already satisfied: attrs>=17.4.0 in /opt/anaconda3/lib/python3.8/site-packages (from jsonschema!=2.5.0,>=2.4->nbformat>=4.4->nbconvert->jupyter>=1.0.0->dltk) (20.3.0)\n"
     ]
    },
    {
     "name": "stdout",
     "output_type": "stream",
     "text": [
      "Requirement already satisfied: pycparser in /opt/anaconda3/lib/python3.8/site-packages (from cffi>=1.0.0->argon2-cffi->notebook->jupyter>=1.0.0->dltk) (2.20)\r\n"
     ]
    }
   ],
   "source": [
    "!pip install SimpleITK\n",
    "import SimpleITK as sitk\n",
    "import numpy as np\n",
    "import pandas as pd\n",
    "import matplotlib.pyplot as plt\n",
    "!pip install dltk\n",
    "from dltk.io import preprocessing\n",
    "from skimage import filters\n",
    "\n",
    "import os"
   ]
  },
  {
   "cell_type": "code",
   "execution_count": 3,
   "metadata": {},
   "outputs": [
    {
     "name": "stdout",
     "output_type": "stream",
     "text": [
      "ERROR! Session/line number was not unique in database. History logging moved to new session 287\n"
     ]
    }
   ],
   "source": [
    "import shutil\n",
    "import os\n",
    "file = '/ADNI'\n",
    "new_path = 'Something'\n",
    "def check_file(file_path):\n",
    "    dst = 'Something'\n",
    "    if file_path.endswith('nii'):\n",
    "        shutil.move(file_path, dst)\n",
    "    else:\n",
    "        if (file_path.endswith('.DS_Store') == False):\n",
    "            sub_folders = os.listdir(file_path)\n",
    "            for sub_folder in sub_folders:\n",
    "                new_path = file_path + '/' + sub_folder\n",
    "                check_file(new_path)"
   ]
  },
  {
   "cell_type": "code",
   "execution_count": null,
   "metadata": {},
   "outputs": [
    {
     "name": "stderr",
     "output_type": "stream",
     "text": [
      "ERROR:root:Internal Python error in the inspect module.\n",
      "Below is the traceback from this internal error.\n",
      "\n",
      "ERROR:root:Internal Python error in the inspect module.\n",
      "Below is the traceback from this internal error.\n",
      "\n",
      "ERROR:root:Internal Python error in the inspect module.\n",
      "Below is the traceback from this internal error.\n",
      "\n"
     ]
    },
    {
     "name": "stdout",
     "output_type": "stream",
     "text": [
      "Traceback (most recent call last):\n",
      "  File \"/opt/anaconda3/lib/python3.8/site-packages/IPython/core/interactiveshell.py\", line 3418, in run_code\n",
      "    exec(code_obj, self.user_global_ns, self.user_ns)\n",
      "  File \"<ipython-input-4-a6747e44df92>\", line 1, in <module>\n",
      "    check_file(file)\n",
      "  File \"<ipython-input-3-34360e2ba2ef>\", line 11, in check_file\n",
      "    sub_folders = os.listdir(file_path)\n",
      "FileNotFoundError: [Errno 2] No such file or directory: '/ADNI'\n",
      "\n",
      "During handling of the above exception, another exception occurred:\n",
      "\n",
      "Traceback (most recent call last):\n",
      "  File \"/opt/anaconda3/lib/python3.8/site-packages/IPython/core/interactiveshell.py\", line 2045, in showtraceback\n",
      "    stb = value._render_traceback_()\n",
      "AttributeError: 'FileNotFoundError' object has no attribute '_render_traceback_'\n",
      "\n",
      "During handling of the above exception, another exception occurred:\n",
      "\n",
      "Traceback (most recent call last):\n",
      "  File \"/opt/anaconda3/lib/python3.8/site-packages/IPython/core/ultratb.py\", line 1170, in get_records\n",
      "    return _fixed_getinnerframes(etb, number_of_lines_of_context, tb_offset)\n",
      "  File \"/opt/anaconda3/lib/python3.8/site-packages/IPython/core/ultratb.py\", line 316, in wrapped\n",
      "    return f(*args, **kwargs)\n",
      "  File \"/opt/anaconda3/lib/python3.8/site-packages/IPython/core/ultratb.py\", line 350, in _fixed_getinnerframes\n",
      "    records = fix_frame_records_filenames(inspect.getinnerframes(etb, context))\n",
      "  File \"/opt/anaconda3/lib/python3.8/inspect.py\", line 1503, in getinnerframes\n",
      "    frameinfo = (tb.tb_frame,) + getframeinfo(tb, context)\n",
      "  File \"/opt/anaconda3/lib/python3.8/inspect.py\", line 1461, in getframeinfo\n",
      "    filename = getsourcefile(frame) or getfile(frame)\n",
      "  File \"/opt/anaconda3/lib/python3.8/inspect.py\", line 708, in getsourcefile\n",
      "    if getattr(getmodule(object, filename), '__loader__', None) is not None:\n",
      "  File \"/opt/anaconda3/lib/python3.8/inspect.py\", line 737, in getmodule\n",
      "    file = getabsfile(object, _filename)\n",
      "  File \"/opt/anaconda3/lib/python3.8/inspect.py\", line 721, in getabsfile\n",
      "    return os.path.normcase(os.path.abspath(_filename))\n",
      "  File \"/opt/anaconda3/lib/python3.8/posixpath.py\", line 379, in abspath\n",
      "    cwd = os.getcwd()\n",
      "FileNotFoundError: [Errno 2] No such file or directory\n",
      "Traceback (most recent call last):\n",
      "  File \"/opt/anaconda3/lib/python3.8/site-packages/IPython/core/interactiveshell.py\", line 3418, in run_code\n",
      "    exec(code_obj, self.user_global_ns, self.user_ns)\n",
      "  File \"<ipython-input-4-a6747e44df92>\", line 1, in <module>\n",
      "    check_file(file)\n",
      "  File \"<ipython-input-3-34360e2ba2ef>\", line 11, in check_file\n",
      "    sub_folders = os.listdir(file_path)\n",
      "FileNotFoundError: [Errno 2] No such file or directory: '/ADNI'\n",
      "\n",
      "During handling of the above exception, another exception occurred:\n",
      "\n",
      "Traceback (most recent call last):\n",
      "  File \"/opt/anaconda3/lib/python3.8/site-packages/IPython/core/interactiveshell.py\", line 2045, in showtraceback\n",
      "    stb = value._render_traceback_()\n",
      "AttributeError: 'FileNotFoundError' object has no attribute '_render_traceback_'\n",
      "\n",
      "During handling of the above exception, another exception occurred:\n",
      "\n",
      "Traceback (most recent call last):\n",
      "  File \"/opt/anaconda3/lib/python3.8/site-packages/IPython/core/interactiveshell.py\", line 3338, in run_ast_nodes\n",
      "    if (await self.run_code(code, result,  async_=asy)):\n",
      "  File \"/opt/anaconda3/lib/python3.8/site-packages/IPython/core/interactiveshell.py\", line 3435, in run_code\n",
      "    self.showtraceback(running_compiled_code=True)\n",
      "  File \"/opt/anaconda3/lib/python3.8/site-packages/IPython/core/interactiveshell.py\", line 2047, in showtraceback\n",
      "    stb = self.InteractiveTB.structured_traceback(etype,\n",
      "  File \"/opt/anaconda3/lib/python3.8/site-packages/IPython/core/ultratb.py\", line 1436, in structured_traceback\n",
      "    return FormattedTB.structured_traceback(\n",
      "  File \"/opt/anaconda3/lib/python3.8/site-packages/IPython/core/ultratb.py\", line 1336, in structured_traceback\n",
      "    return VerboseTB.structured_traceback(\n",
      "  File \"/opt/anaconda3/lib/python3.8/site-packages/IPython/core/ultratb.py\", line 1193, in structured_traceback\n",
      "    formatted_exception = self.format_exception_as_a_whole(etype, evalue, etb, number_of_lines_of_context,\n",
      "  File \"/opt/anaconda3/lib/python3.8/site-packages/IPython/core/ultratb.py\", line 1151, in format_exception_as_a_whole\n",
      "    last_unique, recursion_repeat = find_recursion(orig_etype, evalue, records)\n",
      "  File \"/opt/anaconda3/lib/python3.8/site-packages/IPython/core/ultratb.py\", line 451, in find_recursion\n",
      "    return len(records), 0\n",
      "TypeError: object of type 'NoneType' has no len()\n",
      "\n",
      "During handling of the above exception, another exception occurred:\n",
      "\n",
      "Traceback (most recent call last):\n",
      "  File \"/opt/anaconda3/lib/python3.8/site-packages/IPython/core/interactiveshell.py\", line 2045, in showtraceback\n",
      "    stb = value._render_traceback_()\n",
      "AttributeError: 'TypeError' object has no attribute '_render_traceback_'\n",
      "\n",
      "During handling of the above exception, another exception occurred:\n",
      "\n",
      "Traceback (most recent call last):\n",
      "  File \"/opt/anaconda3/lib/python3.8/site-packages/IPython/core/ultratb.py\", line 1170, in get_records\n",
      "    return _fixed_getinnerframes(etb, number_of_lines_of_context, tb_offset)\n",
      "  File \"/opt/anaconda3/lib/python3.8/site-packages/IPython/core/ultratb.py\", line 316, in wrapped\n",
      "    return f(*args, **kwargs)\n",
      "  File \"/opt/anaconda3/lib/python3.8/site-packages/IPython/core/ultratb.py\", line 350, in _fixed_getinnerframes\n",
      "    records = fix_frame_records_filenames(inspect.getinnerframes(etb, context))\n",
      "  File \"/opt/anaconda3/lib/python3.8/inspect.py\", line 1503, in getinnerframes\n",
      "    frameinfo = (tb.tb_frame,) + getframeinfo(tb, context)\n",
      "  File \"/opt/anaconda3/lib/python3.8/inspect.py\", line 1461, in getframeinfo\n",
      "    filename = getsourcefile(frame) or getfile(frame)\n",
      "  File \"/opt/anaconda3/lib/python3.8/inspect.py\", line 708, in getsourcefile\n",
      "    if getattr(getmodule(object, filename), '__loader__', None) is not None:\n",
      "  File \"/opt/anaconda3/lib/python3.8/inspect.py\", line 737, in getmodule\n",
      "    file = getabsfile(object, _filename)\n",
      "  File \"/opt/anaconda3/lib/python3.8/inspect.py\", line 721, in getabsfile\n",
      "    return os.path.normcase(os.path.abspath(_filename))\n",
      "  File \"/opt/anaconda3/lib/python3.8/posixpath.py\", line 379, in abspath\n",
      "    cwd = os.getcwd()\n",
      "FileNotFoundError: [Errno 2] No such file or directory\n",
      "Traceback (most recent call last):\n",
      "  File \"/opt/anaconda3/lib/python3.8/site-packages/IPython/core/interactiveshell.py\", line 3418, in run_code\n",
      "    exec(code_obj, self.user_global_ns, self.user_ns)\n",
      "  File \"<ipython-input-4-a6747e44df92>\", line 1, in <module>\n",
      "    check_file(file)\n",
      "  File \"<ipython-input-3-34360e2ba2ef>\", line 11, in check_file\n",
      "    sub_folders = os.listdir(file_path)\n",
      "FileNotFoundError: [Errno 2] No such file or directory: '/ADNI'\n",
      "\n",
      "During handling of the above exception, another exception occurred:\n",
      "\n",
      "Traceback (most recent call last):\n",
      "  File \"/opt/anaconda3/lib/python3.8/site-packages/IPython/core/interactiveshell.py\", line 2045, in showtraceback\n",
      "    stb = value._render_traceback_()\n",
      "AttributeError: 'FileNotFoundError' object has no attribute '_render_traceback_'\n",
      "\n",
      "During handling of the above exception, another exception occurred:\n",
      "\n",
      "Traceback (most recent call last):\n",
      "  File \"/opt/anaconda3/lib/python3.8/site-packages/IPython/core/interactiveshell.py\", line 3338, in run_ast_nodes\n",
      "    if (await self.run_code(code, result,  async_=asy)):\n",
      "  File \"/opt/anaconda3/lib/python3.8/site-packages/IPython/core/interactiveshell.py\", line 3435, in run_code\n",
      "    self.showtraceback(running_compiled_code=True)\n",
      "  File \"/opt/anaconda3/lib/python3.8/site-packages/IPython/core/interactiveshell.py\", line 2047, in showtraceback\n",
      "    stb = self.InteractiveTB.structured_traceback(etype,\n",
      "  File \"/opt/anaconda3/lib/python3.8/site-packages/IPython/core/ultratb.py\", line 1436, in structured_traceback\n",
      "    return FormattedTB.structured_traceback(\n",
      "  File \"/opt/anaconda3/lib/python3.8/site-packages/IPython/core/ultratb.py\", line 1336, in structured_traceback\n",
      "    return VerboseTB.structured_traceback(\n",
      "  File \"/opt/anaconda3/lib/python3.8/site-packages/IPython/core/ultratb.py\", line 1193, in structured_traceback\n",
      "    formatted_exception = self.format_exception_as_a_whole(etype, evalue, etb, number_of_lines_of_context,\n",
      "  File \"/opt/anaconda3/lib/python3.8/site-packages/IPython/core/ultratb.py\", line 1151, in format_exception_as_a_whole\n",
      "    last_unique, recursion_repeat = find_recursion(orig_etype, evalue, records)\n",
      "  File \"/opt/anaconda3/lib/python3.8/site-packages/IPython/core/ultratb.py\", line 451, in find_recursion\n",
      "    return len(records), 0\n",
      "TypeError: object of type 'NoneType' has no len()\n",
      "\n",
      "During handling of the above exception, another exception occurred:\n",
      "\n",
      "Traceback (most recent call last):\n",
      "  File \"/opt/anaconda3/lib/python3.8/site-packages/IPython/core/interactiveshell.py\", line 2045, in showtraceback\n",
      "    stb = value._render_traceback_()\n",
      "AttributeError: 'TypeError' object has no attribute '_render_traceback_'\n",
      "\n",
      "During handling of the above exception, another exception occurred:\n",
      "\n",
      "Traceback (most recent call last):\n",
      "  File \"/opt/anaconda3/lib/python3.8/site-packages/IPython/core/interactiveshell.py\", line 2923, in _run_cell\n",
      "    return runner(coro)\n",
      "  File \"/opt/anaconda3/lib/python3.8/site-packages/IPython/core/async_helpers.py\", line 68, in _pseudo_sync_runner\n",
      "    coro.send(None)\n",
      "  File \"/opt/anaconda3/lib/python3.8/site-packages/IPython/core/interactiveshell.py\", line 3146, in run_cell_async\n",
      "    has_raised = await self.run_ast_nodes(code_ast.body, cell_name,\n",
      "  File \"/opt/anaconda3/lib/python3.8/site-packages/IPython/core/interactiveshell.py\", line 3357, in run_ast_nodes\n",
      "    self.showtraceback()\n",
      "  File \"/opt/anaconda3/lib/python3.8/site-packages/IPython/core/interactiveshell.py\", line 2047, in showtraceback\n",
      "    stb = self.InteractiveTB.structured_traceback(etype,\n",
      "  File \"/opt/anaconda3/lib/python3.8/site-packages/IPython/core/ultratb.py\", line 1436, in structured_traceback\n",
      "    return FormattedTB.structured_traceback(\n",
      "  File \"/opt/anaconda3/lib/python3.8/site-packages/IPython/core/ultratb.py\", line 1336, in structured_traceback\n",
      "    return VerboseTB.structured_traceback(\n",
      "  File \"/opt/anaconda3/lib/python3.8/site-packages/IPython/core/ultratb.py\", line 1211, in structured_traceback\n",
      "    formatted_exceptions += self.format_exception_as_a_whole(etype, evalue, etb, lines_of_context,\n",
      "  File \"/opt/anaconda3/lib/python3.8/site-packages/IPython/core/ultratb.py\", line 1151, in format_exception_as_a_whole\n",
      "    last_unique, recursion_repeat = find_recursion(orig_etype, evalue, records)\n",
      "  File \"/opt/anaconda3/lib/python3.8/site-packages/IPython/core/ultratb.py\", line 451, in find_recursion\n",
      "    return len(records), 0\n",
      "TypeError: object of type 'NoneType' has no len()\n",
      "\n",
      "During handling of the above exception, another exception occurred:\n",
      "\n",
      "Traceback (most recent call last):\n",
      "  File \"/opt/anaconda3/lib/python3.8/site-packages/IPython/core/interactiveshell.py\", line 2045, in showtraceback\n",
      "    stb = value._render_traceback_()\n",
      "AttributeError: 'TypeError' object has no attribute '_render_traceback_'\n",
      "\n",
      "During handling of the above exception, another exception occurred:\n",
      "\n",
      "Traceback (most recent call last):\n",
      "  File \"/opt/anaconda3/lib/python3.8/site-packages/IPython/core/ultratb.py\", line 1170, in get_records\n",
      "    return _fixed_getinnerframes(etb, number_of_lines_of_context, tb_offset)\n",
      "  File \"/opt/anaconda3/lib/python3.8/site-packages/IPython/core/ultratb.py\", line 316, in wrapped\n",
      "    return f(*args, **kwargs)\n",
      "  File \"/opt/anaconda3/lib/python3.8/site-packages/IPython/core/ultratb.py\", line 350, in _fixed_getinnerframes\n",
      "    records = fix_frame_records_filenames(inspect.getinnerframes(etb, context))\n",
      "  File \"/opt/anaconda3/lib/python3.8/inspect.py\", line 1503, in getinnerframes\n",
      "    frameinfo = (tb.tb_frame,) + getframeinfo(tb, context)\n",
      "  File \"/opt/anaconda3/lib/python3.8/inspect.py\", line 1461, in getframeinfo\n",
      "    filename = getsourcefile(frame) or getfile(frame)\n",
      "  File \"/opt/anaconda3/lib/python3.8/inspect.py\", line 708, in getsourcefile\n",
      "    if getattr(getmodule(object, filename), '__loader__', None) is not None:\n",
      "  File \"/opt/anaconda3/lib/python3.8/inspect.py\", line 737, in getmodule\n",
      "    file = getabsfile(object, _filename)\n",
      "  File \"/opt/anaconda3/lib/python3.8/inspect.py\", line 721, in getabsfile\n",
      "    return os.path.normcase(os.path.abspath(_filename))\n",
      "  File \"/opt/anaconda3/lib/python3.8/posixpath.py\", line 379, in abspath\n",
      "    cwd = os.getcwd()\n",
      "FileNotFoundError: [Errno 2] No such file or directory\n"
     ]
    }
   ],
   "source": [
    "check_file(file)"
   ]
  },
  {
   "cell_type": "code",
   "execution_count": null,
   "metadata": {},
   "outputs": [],
   "source": []
  }
 ],
 "metadata": {
  "kernelspec": {
   "display_name": "Python 3",
   "language": "python",
   "name": "python3"
  },
  "language_info": {
   "codemirror_mode": {
    "name": "ipython",
    "version": 3
   },
   "file_extension": ".py",
   "mimetype": "text/x-python",
   "name": "python",
   "nbconvert_exporter": "python",
   "pygments_lexer": "ipython3",
   "version": "3.8.5"
  }
 },
 "nbformat": 4,
 "nbformat_minor": 4
}
